<?xml version="1.0" ?>
<!-- =================================================================================== -->
<!-- |    This document was autogenerated by xacro from UNITY_ECM.urdf.xacro           | -->
<!-- |    EDITING THIS FILE BY HAND IS NOT RECOMMENDED                                 | -->
<!-- =================================================================================== -->
<robot name="ecm" xmlns:xacro="http://www.ros.org/wiki/xacro">
  <material name="DaVinciWhite">
    <color rgba="1.0 1.0 1.0 1"/>
  </material>
  <material name="DaVinciLightGray">
    <color rgba="0.8 0.8 0.8 1"/>
  </material>
  <material name="DaVinciMedGray">
    <color rgba="0.6 0.6 0.6 1"/>
  </material>
  <material name="DaVinciDarkGray">
    <color rgba="0.4 0.4 0.4 1"/>
  </material>
  <material name="DaVinciRed">
    <color rgba="0.5 0.4 0.4 1"/>
  </material>
  <material name="DaVinciGreen">
    <color rgba="0.4 0.5 0.4 1"/>
  </material>
  <material name="DaVinciBlue">
    <color rgba="0.4 0.4 0.5 1"/>
  </material>
  <link name="world"/>
  <!-- Joint 0: Fixed to World-->
  <joint name="setup_fixed_joint" type="fixed">
    <parent link="world"/>
    <child link="ecm_setup_base_link"/>
    <origin rpy="0.0 0.0 0.0" xyz="0 0.0 0.0"/>
  </joint>
  <link name="ecm_setup_base_link"/>
  <joint name="setup_tip_joint" type="fixed">
    <parent link="ecm_setup_base_link"/>
    <child link="ecm_setup_link"/>
    <origin rpy="-0.87046370379 0 -1.57079632679" xyz="0.91324 -0.02111 0.03166"/>
    <axis xyz="0 0 1"/>
  </joint>
  <link name="ecm_setup_link">
    <visual>
      <origin rpy="0 0 0" xyz="0 0 0"/>
      <geometry>
        <mesh filename="package://dvrk_model/meshes/ecm/Endo_Arm.STL"/>
      </geometry>
      <material name="DaVinciRed"/>
    </visual>
    <collision>
      <origin rpy="0 0 0" xyz="0 0 0"/>
      <geometry>
        <mesh filename="package://dvrk_model/meshes/ecm/Endo_Arm.STL"/>
      </geometry>
    </collision>
  </link>
  <!-- Joint 0: Fixed to Setup Joint-->
  <joint name="fixed_joint" type="fixed">
    <parent link="ecm_setup_link"/>
    <child link="ecm_base_link"/>
    <origin rpy="0 0 0" xyz="0 0.603 0"/>
  </joint>
  <link name="ecm_base_link"/>
  <!-- Joint 1: Outer Yaw -->
  <joint name="outer_yaw" type="revolute">
    <parent link="ecm_base_link"/>
    <child link="ecm_yaw_link"/>
    <origin rpy="0 -1.57079632679 1.57079632679" xyz="0 0 0"/>
    <axis xyz="0 0 1"/>
    <!--rotates about z axis-->
    <!--limit effort and velocity picked arbitrarily check-->
    <limit effort="50.0" lower="-1.308996939" upper="0.785398163397" velocity="2"/>
    <joint_properties damping="1.0" friction="0.0"/>
  </joint>
  <link name="ecm_yaw_link">
    <visual>
      <origin rpy="0 0 -1.57079632679" xyz="0.0 0 0.603"/>
      <geometry>
        <mesh filename="package://dvrk_model/meshes/ecm/Endo_Link_5.STL"/>
      </geometry>
      <material name="DaVinciGreen"/>
    </visual>
    <collision>
      <origin rpy="0 0 -1.57079632679" xyz="0.0 0 0.603"/>
      <geometry>
        <mesh filename="package://dvrk_model/meshes/ecm/Endo_Link_5.STL"/>
      </geometry>
    </collision>
  </link>
  <!-- Joint 2: Pitch -->
  <joint name="outer_pitch" type="revolute">
    <parent link="ecm_yaw_link"/>
    <child link="ecm_pitch_link"/>
    <origin rpy="-1.57079632679 -1.57079632679 0" xyz="0 0 0"/>
    <axis xyz="0 0 1"/>
    <limit effort="100.0" lower="-0.785398163397" upper="1.1344640138" velocity="10"/>
    <joint_properties damping="1.0" friction="0.0"/>
  </joint>
  <link name="ecm_pitch_link"/>
  <joint name="outer_pitch_0" type="continuous">
    <parent link="ecm_yaw_link"/>
    <child link="ecm_pitch_link_1"/>
    <origin rpy="-1.57079632679 -1.57079632679 0" xyz="0 0 0.378"/>
    <axis xyz="0 0 1"/>
    <joint_properties damping="1.0" friction="0.0"/>
    <mimic joint="outer_pitch" multiplier="1"/>
  </joint>
  <link name="ecm_pitch_link_1">
    <visual>
      <origin rpy="3.14159265359 0 1.37008346282" xyz="0.0 0 0.0"/>
      <geometry>
        <mesh filename="package://dvrk_model/meshes/ecm/Endo_Link_5_2.STL"/>
      </geometry>
      <material name="DaVinciMedGray"/>
    </visual>
    <collision>
      <origin rpy="3.14159265359 0 1.37008346282" xyz="0.0 0 0.0"/>
      <geometry>
        <mesh filename="package://dvrk_model/meshes/ecm/Endo_Link_5_2.STL"/>
      </geometry>
    </collision>
    <inertial>
      <mass value=".9"/>
      <inertia ixx="9.0" ixy="0.0" ixz="0.0" iyy="9.0" iyz="0.0" izz="9.0"/>
    </inertial>
  </link>
  <joint name="outer_pitch_1" type="continuous">
    <parent link="ecm_pitch_link_1"/>
    <child link="ecm_pitch_link_2"/>
    <origin rpy="0 0 0" xyz="0.0558629 0.274575 0"/>
    <axis xyz="0 0 1"/>
    <joint_properties damping="1.0" friction="0.0"/>
    <mimic joint="outer_pitch" multiplier="-1"/>
  </joint>
  <link name="ecm_pitch_link_2">
    <visual>
      <origin rpy="0 0 0" xyz="0.0 0 -0.0225"/>
      <geometry>
        <mesh filename="package://dvrk_model/meshes/ecm/Endo_Link_6_2.STL"/>
      </geometry>
      <material name="DaVinciMedGray"/>
    </visual>
    <collision>
      <origin rpy="0 0 0" xyz="0.0 0 -0.0225"/>
      <geometry>
        <mesh filename="package://dvrk_model/meshes/ecm/Endo_Link_6_2.STL"/>
      </geometry>
    </collision>
    <inertial>
      <mass value=".9"/>
      <inertia ixx="9.0" ixy="0.0" ixz="0.0" iyy="9.0" iyz="0.0" izz="9.0"/>
    </inertial>
  </link>
  <joint name="outer_pitch_2" type="continuous">
    <parent link="ecm_pitch_link_2"/>
    <child link="ecm_pitch_link_3"/>
    <origin rpy="0 0 0" xyz="-0.340 0 0"/>
    <axis xyz="0 0 1"/>
    <joint_properties damping="1.0" friction="0.0"/>
    <mimic joint="outer_pitch" multiplier="1"/>
  </joint>
  <link name="ecm_pitch_link_3">
    <visual>
      <origin rpy="0 0 -1.57079632679" xyz="0.0 0 0.025"/>
      <geometry>
        <mesh filename="package://dvrk_model/meshes/ecm/Endo_Link_7.STL"/>
      </geometry>
      <material name="DaVinciMedGray"/>
    </visual>
    <collision>
      <origin rpy="0 0 -1.57079632679" xyz="0.0 0 0.025"/>
      <geometry>
        <mesh filename="package://dvrk_model/meshes/ecm/Endo_Link_7.STL"/>
      </geometry>
    </collision>
    <inertial>
      <mass value=".9"/>
      <inertia ixx="9.0" ixy="0.0" ixz="0.0" iyy="9.0" iyz="0.0" izz="9.0"/>
    </inertial>
  </link>
  <!-- Joint 3: Insertion -->
  <joint name="insertion" type="prismatic">
    <parent link="ecm_pitch_link"/>
    <child link="ecm_insertion_link"/>
    <origin rpy="1.57079632679 0 0" xyz="0 0.3822 0"/>
    <axis xyz="0 0 1"/>
    <joint_properties damping="1.0" friction="0.0"/>
    <limit effort="100.0" lower="0" upper="0.235" velocity="10"/>
  </joint>
  <link name="ecm_insertion_link">
    <visual>
      <origin rpy="0 0 -1.57079632679" xyz="0.0 0 -0.015"/>
      <geometry>
        <mesh filename="package://dvrk_model/meshes/ecm/Endo_Link_8.STL"/>
      </geometry>
      <material name="DaVinciBlue"/>
    </visual>
    <collision>
      <origin rpy="0 0 -1.57079632679" xyz="0.0 0 -0.015"/>
      <geometry>
        <mesh filename="package://dvrk_model/meshes/ecm/Endo_Link_8.STL"/>
      </geometry>
    </collision>
  </link>
  <!-- Joint 4: Roll -->
  <joint name="outer_roll" type="revolute">
    <parent link="ecm_insertion_link"/>
    <child link="ecm_roll_link"/>
    <origin rpy="0 0 0" xyz="0 0 0.3829"/>
    <axis xyz="0 0 1"/>
    <joint_properties damping="1.0" friction="0.0"/>
    <limit effort="100.0" lower="-1.57079632679" upper="1.57079632679" velocity="10"/>
  </joint>
  <link name="ecm_roll_link">
    <visual>
      <origin rpy="0 0 1.57079632679" xyz="0.0 0 -0.3979"/>
      <geometry>
        <mesh filename="package://dvrk_model/meshes/ecm/EndoScope.STL"/>
      </geometry>
      <material name="DaVinciBlue"/>
    </visual>
    <collision>
      <origin rpy="0 0 1.57079632679" xyz="0.0 0 -0.3979"/>
      <geometry>
        <mesh filename="package://dvrk_model/meshes/ecm/EndoScope.STL"/>
      </geometry>
    </collision>
  </link>
</robot>

