<?xml version="1.0" ?>
<!-- =================================================================================== -->
<!-- |    This document was autogenerated by xacro from MTMR.urdf.xacro          | -->
<!-- |    EDITING THIS FILE BY HAND IS NOT RECOMMENDED                                 | -->
<!-- =================================================================================== -->
<robot name="master" xmlns:xacro="http://www.ros.org/wiki/xacro">
  <material name="DaVinciWhite">
    <color rgba="1.0 1.0 1.0 1"/>
  </material>
  <material name="DaVinciLightGray">
    <color rgba="0.8 0.8 0.8 1"/>
  </material>
  <material name="DaVinciMedGray">
    <color rgba="0.6 0.6 0.6 1"/>
  </material>
  <material name="DaVinciDarkGray">
    <color rgba="0.4 0.4 0.4 1"/>
  </material>
  <material name="DaVinciRed">
    <color rgba="0.5 0.4 0.4 1"/>
  </material>
  <material name="DaVinciGreen">
    <color rgba="0.4 0.5 0.4 1"/>
  </material>
  <material name="DaVinciBlue">
    <color rgba="0.4 0.4 0.5 1"/>
  </material>
  <link name="world"/>
  <!-- Joint 0: Fixed to World-->
  <joint name="fixed" type="fixed">
    <parent link="world"/>
    <child link="top_panel"/>
    <origin rpy="0.0 0.0 0.0" xyz="0.0 0.0 0.0"/>
  </joint>
  <link name="top_panel">
    <visual>
      <origin rpy="0 0 0" xyz="0 0 0.19037"/>
      <geometry>
        <mesh filename="package://dvrk_model/meshes/mtm/Top Panel.dae"/>
      </geometry>
    </visual>
    <collision>
      <origin rpy="0 0 0" xyz="0 0 0.19037"/>
      <geometry>
        <mesh filename="package://dvrk_model/meshes/mtm/Top Panel.STL"/>
      </geometry>
    </collision>
    <inertial>
      <origin rpy="0 0 0" xyz="0 0 0"/>
      <mass value=".9"/>
      <inertia ixx="9.0" ixy="0.0" ixz="0.0" iyy="9.0" iyz="0.0" izz="9.0"/>
    </inertial>
  </link>
  <!-- Joint 1: Outer Yaw -->
  <joint name="outer_yaw" type="revolute">
    <parent link="top_panel"/>
    <child link="outer_yaw_link"/>
    <origin rpy="0 0 1.57079632679" xyz="0 0 0"/>
    <axis xyz="0 0 1"/>
    <!--rotates about z axis-->
    <!--limit effort and velocity picked arbitrarily check-->
    <limit effort="50.0" lower="-1.308996939" upper="0.785398163397" velocity="2"/>
    <joint_properties damping="1.0" friction="0.0"/>
  </joint>
  <link name="outer_yaw_link">
    <visual>
      <origin rpy="0 0 0" xyz="0.025 0 0.19037"/>
      <geometry>
        <mesh filename="package://dvrk_model/meshes/mtm/OutPitch_Shoulder.dae"/>
      </geometry>
    </visual>
    <collision>
      <origin rpy="0 0 0" xyz="0.025 0 0.19037"/>
      <geometry>
        <mesh filename="package://dvrk_model/meshes/mtm/OutPitch_Shoulder.STL"/>
      </geometry>
    </collision>
    <inertial>
      <mass value="1"/>
      <inertia ixx="10.0" ixy="0.0" ixz="0.0" iyy="10.0" iyz="0.0" izz="10.0"/>
    </inertial>
  </link>
  <!-- Joint 2: Shoulder Pitch -->
  <joint name="shoulder_pitch" type="revolute">
    <parent link="outer_yaw_link"/>
    <child link="back_parallel_link"/>
    <!-- xyz= 0 0 -.19037-->
    <origin rpy="-1.57079632679 -1.57079632679 0" xyz="0 0 0"/>
    <axis xyz="0 0 1"/>
    <!--limit effort and velocity picked arbitrarily check-->
    <limit effort="100.0" lower="-0.785398163397" upper="0.785398163397" velocity="10"/>
    <joint_properties damping="1.0" friction="0.0"/>
  </joint>
  <link name="back_parallel_link">
    <visual>
      <geometry>
        <mesh filename="package://dvrk_model/meshes/mtm/ArmParallel.dae"/>
      </geometry>
    </visual>
    <collision>
      <geometry>
        <mesh filename="package://dvrk_model/meshes/mtm/ArmParallel.STL"/>
      </geometry>
    </collision>
    <inertial>
      <mass value=".9"/>
      <inertia ixx="9.0" ixy="0.0" ixz="0.0" iyy="9.0" iyz="0.0" izz="9.0"/>
    </inertial>
  </link>
  <joint name="shoulder_pitch_parallel" type="revolute">
    <parent link="outer_yaw_link"/>
    <child link="top_parallel_link"/>
    <origin rpy="-1.57079632679 -1.57079632679 0" xyz="0 0 0"/>
    <axis xyz="0 0 1"/>
    <!--rotates about  x axis-->
    <!--limit effort and velocity picked arbitrarily check-->
    <limit effort="100.0" lower="-1.57079632679" upper="1.57079632679" velocity="10"/>
    <joint_properties damping="1.0" friction="0.0"/>
    <mimic joint="shoulder_pitch" multiplier="1"/>
  </joint>
  <link name="top_parallel_link">
    <visual>
      <origin rpy="0 0 -1.57079632679" xyz="0 0 0.065"/>
      <geometry>
        <mesh filename="package://dvrk_model/meshes/mtm/ArmParallel1.dae"/>
      </geometry>
    </visual>
    <collision>
      <origin rpy="0 0 0" xyz="0 0 0"/>
      <geometry>
        <mesh filename="package://dvrk_model/meshes/mtm/ArmParallel1.STL"/>
      </geometry>
    </collision>
    <inertial>
      <mass value=".5"/>
      <inertia ixx="5.0" ixy="0.0" ixz="0.0" iyy="5.0" iyz="0.0" izz="5.0"/>
    </inertial>
  </link>
  <!-- Joint 3: Elbow Pitch -->
  <joint name="elbow_pitch" type="revolute">
    <parent link="back_parallel_link"/>
    <child link="bottom_parallel_link"/>
    <!-- xyz= -->
    <origin rpy="0 0 1.57079632679" xyz="-0.2794 0 0"/>
    <axis xyz="0 0 1"/>
    <!--limit effort and velocity picked arbitrarily check-->
    <limit effort="100.0" lower="-0.785398163397" upper="0.785398163397" velocity="10"/>
    <joint_properties damping="1.0" friction="0.0"/>
  </joint>
  <link name="bottom_parallel_link">
    <visual>
      <geometry>
        <mesh filename="package://dvrk_model/meshes/mtm/BottomArm.dae"/>
      </geometry>
    </visual>
    <collision>
      <geometry>
        <mesh filename="package://dvrk_model/meshes/mtm/BottomArm.STL"/>
      </geometry>
    </collision>
    <inertial>
      <mass value="0.8"/>
      <inertia ixx="0.1" ixy="0.0" ixz="0.0" iyy="0.1" iyz="0.0" izz="0.1"/>
    </inertial>
  </link>
  <transmission name="tran1">
    <type>transmission_interface/SimpleTransmission</type>
    <joint name="outer_yaw"/>
    <actuator name="motor1">
      <hardwareInterface>EffortJointInterface</hardwareInterface>
      <mechanicalReduction>1</mechanicalReduction>
    </actuator>
  </transmission>
  <transmission name="tran2">
    <type>transmission_interface/SimpleTransmission</type>
    <joint name="shoulder_pitch"/>
    <actuator name="motor2">
      <hardwareInterface>EffortJointInterface</hardwareInterface>
      <mechanicalReduction>1</mechanicalReduction>
    </actuator>
  </transmission>
  <transmission name="tran3">
    <type>transmission_interface/SimpleTransmission</type>
    <joint name="elbow_pitch"/>
    <actuator name="motor3">
      <hardwareInterface>EffortJointInterface</hardwareInterface>
      <mechanicalReduction>1</mechanicalReduction>
    </actuator>
  </transmission>
  <gazebo>
    <plugin filename="libgazebo_ros_control.so" name="gazebo_ros_control">
      <robotNamespace>/mtm</robotNamespace>
    </plugin>
  </gazebo>
  <gazebo>
    <plugin filename="libgazebo_ros_f3d.so" name="force_torque_sensor">
      <bodyName>bottom_parallel_link</bodyName>
      <frameName>bottom_parallel_link</frameName>
      <topicName>/force_torque_feedback</topicName>
      <alwaysOn>true</alwaysOn>
      <updateRate>100.0</updateRate>
    </plugin>
  </gazebo>
  <!-- Joint 4: Platform -->
  <joint name="wrist_platform" type="revolute">
    <parent link="bottom_parallel_link"/>
    <child link="wrist_platform_link"/>
    <origin rpy="1.57079632679 0 0" xyz="-0.3645 -0.1506 0.0"/>
    <axis xyz="0 0 1"/>
    <!--rotates about z axis-->
    <!--limit effort and velocity picked arbitrarily check-->
    <limit effort="100.0" lower="-1.0471975512" upper="4.27605666739" velocity="10"/>
    <joint_properties damping="1.0" friction="0.0"/>
  </joint>
  <link name="wrist_platform_link">
    <visual>
      <geometry>
        <mesh filename="package://dvrk_model/meshes/mtm/WristPlatform.dae"/>
      </geometry>
    </visual>
    <collision>
      <geometry>
        <mesh filename="package://dvrk_model/meshes/mtm/WristPlatform.STL"/>
      </geometry>
    </collision>
    <inertial>
      <mass value="0.4"/>
      <inertia ixx="0.1" ixy="0.0" ixz="0.0" iyy="0.1" iyz="0.0" izz="0.1"/>
    </inertial>
  </link>
  <!-- Joint 5: Wrist Pitch -->
  <joint name="wrist_pitch" type="revolute">
    <parent link="wrist_platform_link"/>
    <child link="wrist_pitch_link"/>
    <origin rpy="-1.57079632679 0 0" xyz="0 0 0"/>
    <axis xyz="0 0 1"/>
    <!--limit effort and velocity picked arbitrarily check-->
    <limit effort="100.0" lower="-1.57079632679" upper="3.14159265359" velocity="10"/>
    <joint_properties damping="1.0" friction="0.0"/>
  </joint>
  <link name="wrist_pitch_link">
    <visual>
      <!-- defined from CAD file (increased in the y dir by .005-->
      <geometry>
        <mesh filename="package://dvrk_model/meshes/mtm/WristPitch.dae"/>
      </geometry>
    </visual>
    <collision>
      <!-- defined from CAD file (increased in the y dir by .005-->
      <geometry>
        <mesh filename="package://dvrk_model/meshes/mtm/WristPitch.STL"/>
      </geometry>
    </collision>
    <inertial>
      <mass value="0.2"/>
      <inertia ixx="0.1" ixy="0.0" ixz="0.0" iyy="0.1" iyz="0.0" izz="0.1"/>
    </inertial>
  </link>
  <!-- Joint 6: Wrist Yaw-->
  <joint name="wrist_yaw" type="revolute">
    <parent link="wrist_pitch_link"/>
    <child link="wrist_yaw_link"/>
    <!--  defined from CAD file-->
    <origin rpy="1.57079632679 -1.57079632679 0" xyz="0 0 0"/>
    <axis xyz="0 0 1"/>
    <!--rotates about z axis-->
    <!--limit effort and velocity picked arbitrarily check-->
    <limit effort="100.0" lower="-0.785398163397" upper="0.785398163397" velocity="10"/>
    <joint_properties damping="1.0" friction="0.0"/>
  </joint>
  <link name="wrist_yaw_link">
    <visual>
      <geometry>
        <mesh filename="package://dvrk_model/meshes/mtm/WristYaw.dae"/>
      </geometry>
    </visual>
    <collision>
      <geometry>
        <mesh filename="package://dvrk_model/meshes/mtm/WristYaw.STL"/>
      </geometry>
    </collision>
    <inertial>
      <mass value="0.2"/>
      <inertia ixx="0.1" ixy="0.0" ixz="0.0" iyy="0.1" iyz="0.0" izz="0.1"/>
    </inertial>
  </link>
  <!-- Joint 7: Wrist Roll -->
  <joint name="wrist_roll" type="revolute">
    <parent link="wrist_yaw_link"/>
    <child link="wrist_roll_link"/>
    <!-- -.039 & .055 defined from CAD file-->
    <!-- <origin rpy="${-PI/2} ${PI/2} 0" xyz="0 -.039 0"/> -->
    <origin rpy="0 -1.57079632679 1.57079632679" xyz="0 0 0"/>
    <axis xyz="0 0 1"/>
    <!--limit effort and velocity picked arbitrarily check-->
    <limit effort="100.0" lower="-4.71238898038" upper="4.71238898038" velocity="10"/>
    <joint_properties damping="1.0" friction="0.0"/>
  </joint>
  <link name="wrist_roll_link">
    <visual>
      <origin rpy="3.14159265359 0 0" xyz="0 0 0.039"/>
      <geometry>
        <mesh filename="package://dvrk_model/meshes/mtm/WristRoll.dae"/>
      </geometry>
    </visual>
    <collision>
      <origin rpy="3.14159265359 0 0" xyz="0 0 0.039"/>
      <geometry>
        <mesh filename="package://dvrk_model/meshes/mtm/WristRoll.STL"/>
      </geometry>
    </collision>
    <inertial>
      <mass value="0.1"/>
      <inertia ixx="0.1" ixy="0.0" ixz="0.0" iyy="0.1" iyz="0.0" izz="0.1"/>
    </inertial>
  </link>
  <transmission name="tran4">
    <type>transmission_interface/SimpleTransmission</type>
    <joint name="wrist_platform"/>
    <actuator name="motor4">
      <hardwareInterface>EffortJointInterface</hardwareInterface>
      <mechanicalReduction>1</mechanicalReduction>
    </actuator>
  </transmission>
  <transmission name="tran5">
    <type>transmission_interface/SimpleTransmission</type>
    <joint name="wrist_pitch"/>
    <actuator name="motor5">
      <hardwareInterface>EffortJointInterface</hardwareInterface>
      <mechanicalReduction>1</mechanicalReduction>
    </actuator>
  </transmission>
  <transmission name="tran6">
    <type>transmission_interface/SimpleTransmission</type>
    <joint name="wrist_yaw"/>
    <actuator name="motor6">
      <hardwareInterface>EffortJointInterface</hardwareInterface>
      <mechanicalReduction>1</mechanicalReduction>
    </actuator>
  </transmission>
  <transmission name="tran7">
    <type>transmission_interface/SimpleTransmission</type>
    <joint name="wrist_roll"/>
    <actuator name="motor7">
      <hardwareInterface>EffortJointInterface</hardwareInterface>
      <mechanicalReduction>1</mechanicalReduction>
    </actuator>
  </transmission>
</robot>

