<?xml version="1.0" ?>
<!-- =================================================================================== -->
<!-- |    This document was autogenerated by xacro from UNITY_PSM_SNAKE.urdf.xacro     | -->
<!-- |    EDITING THIS FILE BY HAND IS NOT RECOMMENDED                                 | -->
<!-- =================================================================================== -->
<robot name="dvrk_psm" xmlns:xacro="http://www.ros.org/wiki/xacro">
  <material name="DaVinciWhite">
    <color rgba="1.0 1.0 1.0 1"/>
  </material>
  <material name="DaVinciLightGray">
    <color rgba="0.8 0.8 0.8 1"/>
  </material>
  <material name="DaVinciMedGray">
    <color rgba="0.6 0.6 0.6 1"/>
  </material>
  <material name="DaVinciDarkGray">
    <color rgba="0.4 0.4 0.4 1"/>
  </material>
  <material name="DaVinciRed">
    <color rgba="0.5 0.4 0.4 1"/>
  </material>
  <material name="DaVinciGreen">
    <color rgba="0.4 0.5 0.4 1"/>
  </material>
  <material name="DaVinciBlue">
    <color rgba="0.4 0.4 0.5 1"/>
  </material>
  <link name="world"/>
  <!-- fixed joint -->
  <joint name="fixed" type="fixed">
    <parent link="world"/>
    <child link="unity_psm_base_link"/>
    <origin rpy="0.0 0.0 3.1415926" xyz="0.0 0.0 0.0"/>
  </joint>
  <!-- link 0: psm base link -->
  <link name="unity_psm_base_link">
    <visual>
      <origin rpy="1.5708 0 3.1416" xyz="0.039 -0.40788 -0.07879"/>
      <geometry>
        <mesh filename="package://dvrk_model/meshes/psm/psm_base.dae"/>
      </geometry>
    </visual>
  </link>
  <!-- joint 1 -->
  <joint name="outer_yaw" type="revolute">
    <parent link="unity_psm_base_link"/>
    <child link="unity_outer_yaw_link"/>
    <axis xyz="0 0 1"/>
    <!-- <origin rpy="1.5708 -1.5708 0" xyz="0.0 -0.369 0.0"/> -->
    <origin rpy="0 -1.5708 1.5708" xyz="0.0 0.0 0.0"/>
    <limit effort="1000" lower="-1.5707" upper="1.5707" velocity=".4"/>
  </joint>
  <!-- link 1: outer_yaw -->
  <link name="unity_outer_yaw_link">
    <visual>
      <!-- <origin rpy="0 0 -1.5708" xyz="0.0125 0 0.1575"/> -->
      <origin rpy="3.1416 0 1.5708" xyz="0.0125 0 0.5265"/>
      <geometry>
        <mesh filename="package://dvrk_model/meshes/psm/outer_yaw.dae"/>
      </geometry>
    </visual>
  </link>
  <!-- Note: I can not put visual link here as it's parallel -->
  <!-- mechanism, so the outer_pitch_link does not have visual -->
  <!-- link, all visual links mimic outer_pitch value -->
  <!-- joint 2: outer_pitch -->
  <joint name="outer_pitch" type="revolute">
    <parent link="unity_outer_yaw_link"/>
    <child link="unity_outer_pitch_link"/>
    <axis xyz="0 0 1"/>
    <origin rpy="-1.5708 -1.5708 0" xyz="0 0 0"/>
    <limit effort="1000" lower="-0.7854" upper="0.7854" velocity=".4"/>
  </joint>
  <!-- link 2: outer_pitch_link -->
  <link name="unity_outer_pitch_link"/>
  <!-- joint 2-1: outer_pitch_1 -->
  <joint name="outer_pitch_1" type="continuous">
    <parent link="unity_outer_yaw_link"/>
    <child link="unity_outer_pitch_back_link"/>
    <axis xyz="0 0 1"/>
    <!-- <origin rpy="-1.5708 -1.5708 0" xyz="0 0.0295 0.1495"/> -->
    <origin rpy="-1.5708 -1.5708 0" xyz="0 0.0295 0.5185"/>
    <mimic joint="outer_pitch" multiplier="1"/>
  </joint>
  <!-- link 2-1: outer_pitch_back -->
  <link name="unity_outer_pitch_back_link">
    <visual>
      <origin rpy="0 0 -0.27129" xyz="0 0 0"/>
      <geometry>
        <mesh filename="package://dvrk_model/meshes/psm/outer_pitch_back.dae"/>
      </geometry>
    </visual>
  </link>
  <!-- joint 2-2: outer_pitch_2 -->
  <joint name="outer_pitch_2" type="continuous">
    <parent link="unity_outer_yaw_link"/>
    <child link="unity_outer_pitch_front_link"/>
    <axis xyz="0 0 1"/>
    <origin rpy="-1.5708 -1.5708 0" xyz="0 0.0295 0.4285"/>
    <mimic joint="outer_pitch" multiplier="1"/>
  </joint>
  <!-- link 2-2: outer_pitch_front -->
  <link name="unity_outer_pitch_front_link">
    <visual>
      <origin rpy="0 0 -0.27129" xyz="0 0 0"/>
      <geometry>
        <mesh filename="package://dvrk_model/meshes/psm/outer_pitch_front.dae"/>
      </geometry>
    </visual>
  </link>
  <!-- joint 2-3: outer_pitch_3 -->
  <joint name="outer_pitch_3" type="continuous">
    <parent link="unity_outer_pitch_back_link"/>
    <child link="unity_outer_pitch_bottom_link"/>
    <axis xyz="0 0 1"/>
    <origin rpy="0 0 0" xyz="0.04178 0.15007 -0.0137"/>
    <mimic joint="outer_pitch" multiplier="-1"/>
  </joint>
  <!-- link 2-3: outer_pitch_bottom -->
  <link name="unity_outer_pitch_bottom_link">
    <visual>
      <origin rpy="0 -1.5708 0" xyz="0.009 0 0"/>
      <geometry>
        <mesh filename="package://dvrk_model/meshes/psm/outer_pitch_bottom.dae"/>
      </geometry>
    </visual>
  </link>
  <!-- joint 2-4: outer_pitch_4 -->
  <joint name="outer_pitch_4" type="continuous">
    <parent link="unity_outer_pitch_back_link"/>
    <child link="unity_outer_pitch_top_link"/>
    <axis xyz="0 0 1"/>
    <origin rpy="0 0 0" xyz="0.04209 0.18695 -0.02412"/>
    <mimic joint="outer_pitch" multiplier="-1"/>
  </joint>
  <!-- link 2-4: outer_pitch_top -->
  <link name="unity_outer_pitch_top_link">
    <visual>
      <origin rpy="0 -1.5708 0" xyz="0.009 0 0"/>
      <geometry>
        <mesh filename="package://dvrk_model/meshes/psm/outer_pitch_top.dae"/>
      </geometry>
    </visual>
  </link>
  <!-- joint 2-5: outer_pitch_5 -->
  <joint name="outer_pitch_5" type="continuous">
    <parent link="unity_outer_pitch_bottom_link"/>
    <child link="unity_outer_insertion_link"/>
    <axis xyz="0 0 1"/>
    <origin rpy="0 0 0" xyz="-0.520 0 -0.0155"/>
    <mimic joint="outer_pitch" multiplier="1"/>
  </joint>
  <!-- link 2-5: outer_insertion -->
  <link name="unity_outer_insertion_link">
    <visual>
      <origin rpy="0 -1.5708 1.5708" xyz="0.02528 0.429 0"/>
      <geometry>
        <mesh filename="package://dvrk_model/meshes/psm/outer_insertion.dae"/>
      </geometry>
    </visual>
  </link>
  <!-- joint 3: insertion -->
  <joint name="outer_insertion" type="prismatic">
    <!-- <parent link="${prefix}outer_insertion_link"/> -->
    <!-- <parent link="${prefix}psm_base_link"/> -->
    <parent link="unity_outer_pitch_link"/>
    <child link="unity_tool_main_link"/>
    <axis xyz="0 0 1"/>
    <origin rpy="1.5708 0 0" xyz="0 0.4318 0"/>
    <limit effort="1000" lower="0" upper="0.240" velocity=".4"/>
  </joint>
  <!-- link 3: tool_main_link -->
  <link name="unity_tool_main_link">
    <visual>
      <origin rpy="0 0 1.5708" xyz="0 0 0.041"/>
      <geometry>
        <mesh filename="package://dvrk_model/meshes/psm/tool_main.dae"/>
      </geometry>
    </visual>
  </link>
  <!-- joint 4: Outer Roll -->
  <joint name="outer_roll" type="revolute">
    <parent link="unity_tool_main_link"/>
    <child link="unity_tool_wrist_link"/>
    <axis xyz="0 0 1"/>
    <origin rpy="0 0 0" xyz="0 0 0.4162"/>
    <limit effort="1000" lower="-2.2689" upper="2.2689" velocity=".4"/>
  </joint>
  <!-- link 4: tool_wrist_link -->
  <link name="unity_tool_wrist_link">
    <visual>
      <origin rpy="0 0 1.5708" xyz="0 0 -0.0091"/>
      <geometry>
        <mesh filename="package://dvrk_model/meshes/psm/tool_wrist_link.dae"/>
      </geometry>
    </visual>
  </link>
  <!-- joint 4-1: outer roll shaft joint FIXED-->
  <joint name="outer_roll_shaft" type="fixed">
    <parent link="unity_tool_wrist_link"/>
    <child link="unity_tool_wrist_shaft_link"/>
    <axis xyz="0 0 1"/>
    <origin rpy="0 0 0" xyz="0 0 0.0"/>
  </joint>
  <!-- link 4-1: tool_wrist_shaft_link -->
  <link name="unity_tool_wrist_shaft_link">
    <visual>
      <origin rpy="1.5708 0 0" xyz="0 0.00401 0"/>
      <geometry>
        <mesh filename="package://dvrk_model/meshes/psm/tool_wrist_shaft_link.dae"/>
      </geometry>
    </visual>
  </link>
  <!-- joint 6: Outer wrist pitch1 joint -->
  <joint name="outer_wrist_pitch1" type="revolute">
    <parent link="unity_tool_wrist_shaft_link"/>
    <child link="unity_tool_snake_disc1_link"/>
    <axis xyz="0 0 1"/>
    <origin rpy="-1.5708 -1.5708 0" xyz="0.0 0 0"/>
    <limit effort="1000" lower="-1.3963" upper="1.3963" velocity=".4"/>
  </joint>
  <!-- link 6: tool_snake_disc1_link -->
  <link name="unity_tool_snake_disc1_link">
    <visual>
      <origin rpy="1.5708 0 0" xyz="0.0027 0 0"/>
      <geometry>
        <mesh filename="package://dvrk_model/meshes/psm/snake_tool/link_1.STL"/>
      </geometry>
    </visual>
  </link>
  <!-- joint 7: Outer wrist yaw1 joint -->
  <joint name="outer_wrist_yaw1" type="revolute">
    <parent link="unity_tool_snake_disc1_link"/>
    <child link="unity_tool_snake_disc2_link"/>
    <axis xyz="0 0 1"/>
    <origin rpy="-1.5708 0 0" xyz="0.0034 0 0"/>
    <limit effort="1000" lower="-1.3963" upper="1.3963" velocity=".4"/>
  </joint>
  <!-- link 7: tool_snake_disc2_link -->
  <link name="unity_tool_snake_disc2_link">
    <visual>
      <origin rpy="1.5708 0 0" xyz="0.0027 0 0"/>
      <geometry>
        <mesh filename="package://dvrk_model/meshes/psm/snake_tool/link_2.STL"/>
      </geometry>
    </visual>
  </link>
  <!-- joint 8: Outer wrist yaw2 joint -->
  <joint name="outer_wrist_yaw2" type="revolute">
    <parent link="unity_tool_snake_disc2_link"/>
    <child link="unity_tool_snake_disc3_link"/>
    <axis xyz="0 0 1"/>
    <origin rpy="0 0 0" xyz="0.0034 0 0"/>
    <limit effort="1000" lower="-1.3963" upper="1.3963" velocity=".4"/>
  </joint>
  <!-- link 8: tool_snake_disc3_link -->
  <link name="unity_tool_snake_disc3_link">
    <visual>
      <origin rpy="1.5708 0 0" xyz="0.0027 0 0"/>
      <geometry>
        <mesh filename="package://dvrk_model/meshes/psm/snake_tool/link_3.STL"/>
      </geometry>
    </visual>
  </link>
  <!-- joint 9: Outer wrist pitch2 joint -->
  <joint name="outer_wrist_pitch2" type="revolute">
    <parent link="unity_tool_snake_disc3_link"/>
    <child link="unity_tool_snake_end_link"/>
    <axis xyz="0 0 1"/>
    <origin rpy="1.5708 -1.5708 0" xyz="0.0034 0 0"/>
    <limit effort="1000" lower="-1.3963" upper="1.3963" velocity=".4"/>
  </joint>
  <!-- link 9: tool_snake_end_link -->
  <link name="unity_tool_snake_end_link">
    <visual>
      <origin rpy="0 1.5708 0" xyz="0 -0.0027 0"/>
      <geometry>
        <mesh filename="package://dvrk_model/meshes/psm/snake_tool/link_4.STL"/>
      </geometry>
    </visual>
  </link>
  <!-- Gripper  -->
  <!-- joint 11-0: Outer open angle 1  -->
  <joint name="jaw" type="revolute">
    <parent link="unity_tool_snake_end_link"/>
    <child link="unity_tool_wrist_snake_ee_link_0"/>
    <axis xyz="0 0 1"/>
    <origin rpy="0 0 0" xyz="0 0 0"/>
    <limit effort="1000" lower="0" upper="1.5707" velocity=".4"/>
  </joint>
  <!-- link 11-0: Outer open angle virtual -->
  <link name="unity_tool_wrist_snake_ee_link_0">
    <visual>
      <origin rpy="0 0 0" xyz="0 0 0.0"/>
      <geometry>
        <box size="0 0 0"/>
      </geometry>
    </visual>
  </link>
  <!-- joint 11-1: Outer open angle 1  -->
  <joint name="jaw_mimic_1" type="revolute">
    <parent link="unity_tool_snake_end_link"/>
    <child link="unity_tool_wrist_snake_ee_link_1"/>
    <axis xyz="0 0 1"/>
    <origin rpy="0 2.3562 0" xyz="0 -0.01 0"/>
    <limit effort="1000" lower="-1.5707" upper="1.5707" velocity=".4"/>
    <mimic joint="jaw" multiplier="0.5"/>
  </joint>
  <!-- link 11-1: Outer open angle link 1 -->
  <link name="unity_tool_wrist_snake_ee_link_1">
    <visual>
      <origin rpy="-1.5708 -0.7854 0" xyz="0 0 0"/>
      <geometry>
        <mesh filename="package://dvrk_model/meshes/psm/snake_tool/gripper_2.STL"/>
      </geometry>
    </visual>
  </link>
  <!-- joint 11-2: Outer open angle 2   -->
  <joint name="jaw_mimic_2" type="revolute">
    <parent link="unity_tool_snake_end_link"/>
    <child link="unity_tool_wrist_snake_ee_link_2"/>
    <axis xyz="0 0 1"/>
    <origin rpy="0 2.3562 0" xyz="0 -0.01 0"/>
    <limit effort="1000" lower="-1.5707" upper="1.5707" velocity=".4"/>
    <mimic joint="jaw" multiplier="-0.5"/>
  </joint>
  <!-- link 11-2: Outer open angle link 2 -->
  <link name="unity_tool_wrist_snake_ee_link_2">
    <visual>
      <origin rpy="-1.5708 2.3561 0" xyz="0 0 0"/>
      <geometry>
        <mesh filename="package://dvrk_model/meshes/psm/snake_tool/gripper_3.STL"/>
      </geometry>
    </visual>
  </link>
</robot>

